<?xml version="1.0" ?>
<!-- =================================================================================== -->
<!-- |    This document was autogenerated by xacro from hexa_leg.xacro                 | -->
<!-- |    EDITING THIS FILE BY HAND IS NOT RECOMMENDED                                 | -->
<!-- =================================================================================== -->
<robot name="hexa_leg_pod">
  <material name="silver_default">
    <color rgba="0.700 0.700 0.700 1.000"/>
  </material>
  <material name="steel_satin">
    <color rgba="0.6274509803921569 0.6274509803921569 0.6274509803921569 1.0"/>
  </material>
  <!--bodyの半径[m]-->
  <joint name="body_joint" type="fixed">
    <parent link="base_link"/>
    <child link="body_link"/>
  </joint>
  <link name="base_link"/>
  <!--baselink設定-->
  <link name="body_link">
    <!--body設定-->
    <inertial>
      <origin rpy="0 0 0" xyz="0 0 0"/>
      <mass value="0.870"/>
      <inertia ixx="0.1" ixy="0.0" ixz="0.0" iyy="0.1" iyz="0.0" izz="0.1"/>
    </inertial>
    <visual>
      <origin rpy="0 0 0" xyz="0 0 0"/>
      <geometry>
        <mesh filename="package://dual_leg_controller/model/meshes/base_link.stl" scale="0.001 0.001 0.001"/>
      </geometry>
      <material name="gray">
        <color rgba="0.7 0.7 0.7 1.0"/>
      </material>
    </visual>
    <collision>
      <origin rpy="0 0 0" xyz="0 0 0"/>
      <geometry>
        <mesh filename="package://dual_leg_controller/model/meshes/base_link.stl" scale="0.001 0.001 0.001"/>
      </geometry>
    </collision>
  </link>
  <!-- モーターの設定 -->
  <link name="motor0">
    <!--  物理シミュレーションのための質量特性を定義 -->
    <inertial>
      <!-- 慣性フレームの位置と向き -->
      <origin rpy="0 0 0" xyz="0 0 0"/>
      <!-- 部品の質量（kg単位） -->
      <mass value="0.125"/>
      <!--  慣性テンソル（物体の回転に対する抵抗を定義する行列） -->
      <!-- ixx, iyy, izz - 各軸周りの慣性モーメント -->
      <!-- ixy, iyz, ixz - 慣性乗積（オフ対角成分） -->
      <inertia ixx="0.1" ixy="0.0" ixz="0.0" iyy="0.1" iyz="0.0" izz="0.1"/>
    </inertial>
    <!-- 視覚・表示の設定 -->
    <visual>
      <!-- 表示モデルの位置と向き -->
      <origin rpy="0 0 0" xyz="0 0.005 0"/>
      <!--  形状を定義 -->
      <geometry>
        <mesh filename="package://dual_leg_controller/model/meshes/motor.stl" scale="0.001 0.001 0.001"/>
      </geometry>
      <material name="steel_satin"/>
    </visual>
    <!-- 衝突検出形状 (物理シミュレーション用)の設定 -->
    <collision>
      <!-- 衝突モデルの位置と向き -->
      <origin rpy="0 0 0" xyz="0 0.005 0"/>
      <!--  形状を定義 -->
      <geometry>
        <mesh filename="package://dual_leg_controller/model/meshes/motor.stl" scale="0.001 0.001 0.001"/>
      </geometry>
    </collision>
  </link>
  <!-- coxa_motor と femur_motor をつなぐリンク(leg_coxa)の定義  -->
  <link name="limb0_link2">
    <!--  物理シミュレーションのための質量特性を定義 -->
    <inertial>
      <origin rpy="0 0 0" xyz="0 0 0"/>
      <mass value="0.125"/>
      <inertia ixx="0.1" ixy="0.0" ixz="0.0" iyy="0.1" iyz="0.0" izz="0.1"/>
    </inertial>
    <!-- 視覚・表示の設定 -->
    <visual>
      <origin rpy="0 -1.5707963267948966 0" xyz="0 0 -0.045"/>
      <geometry>
        <mesh filename="package://dual_leg_controller/model/meshes/link1_1.stl" scale="0.001 0.001 0.001"/>
      </geometry>
      <material name="steel_satin"/>
    </visual>
    <!-- 衝突検出形状 (物理シミュレーション用)の設定 -->
    <collision>
      <origin rpy="0 -1.5707963267948966 0" xyz="0 0 -0.045"/>
      <geometry>
        <mesh filename="package://dual_leg_controller/model/meshes/link1_1.stl" scale="0.001 0.001 0.001"/>
      </geometry>
    </collision>
  </link>
  <!-- femur_motor と tibia_motor をつなぐリンク(leg_fumer)の定義  -->
  <link name="limb0_link4">
    <inertial>
      <mass value="0.125"/>
      <inertia ixx="0.1" ixy="0.0" ixz="0.0" iyy="0.1" iyz="0.0" izz="0.1"/>
    </inertial>
    <visual>
      <origin rpy="0 3.141592653589793 -1.5707963267948966" xyz="0.05 -0.055 0"/>
      <geometry>
        <mesh filename="package://dual_leg_controller/model/meshes/link2_1.stl" scale="0.001 0.001 0.001"/>
      </geometry>
      <material name="steel_satin"/>
    </visual>
    <collision>
      <origin rpy="0 3.141592653589793 -1.5707963267948966" xyz="0.05 -0.055 0"/>
      <geometry>
        <mesh filename="package://dual_leg_controller/model/meshes/link2_1.stl" scale="0.001 0.001 0.001"/>
      </geometry>
    </collision>
  </link>
  <link name="limb0_link6">
    <inertial>
      <origin rpy="0 0 0" xyz="0 0 0"/>
      <mass value="0.125"/>
      <inertia ixx="0.1" ixy="0.0" ixz="0.0" iyy="0.1" iyz="0.0" izz="0.1"/>
    </inertial>
    <visual>
      <origin rpy="3.141592653589793 0 3.141592653589793" xyz="0.055 0.038 0"/>
      <geometry>
        <mesh filename="package://dual_leg_controller/model/meshes/link3_1.stl" scale="0.001 0.001 0.001"/>
      </geometry>
      <material name="steel_satin"/>
    </visual>
    <collision>
      <origin rpy="3.141592653589793 0 3.141592653589793" xyz="0.055 0.038 0"/>
      <geometry>
        <mesh filename="package://dual_leg_controller/model/meshes/link3_1.stl" scale="0.001 0.001 0.001"/>
      </geometry>
    </collision>
    <!-- 座標系確認用の軸表示を追加 -->
    <visual name="debug_x_axis">
      <origin rpy="0 1.5707963267948966 0" xyz="0.02 0 0"/>
      <geometry>
        <cylinder length="0.04" radius="0.002"/>
      </geometry>
      <material name="debug_red">
        <color rgba="1.0 0.0 0.0 1.0"/>
      </material>
    </visual>
    <visual name="debug_y_axis">
      <origin rpy="1.5707963267948966 0 0" xyz="0 0.02 0"/>
      <geometry>
        <cylinder length="0.04" radius="0.002"/>
      </geometry>
      <material name="debug_green">
        <color rgba="0.0 1.0 0.0 1.0"/>
      </material>
    </visual>
    <visual name="debug_z_axis">
      <origin rpy="0 0 0" xyz="0 0 0.02"/>
      <geometry>
        <cylinder length="0.04" radius="0.002"/>
      </geometry>
      <material name="debug_blue">
        <color rgba="0.0 0.0 1.0 1.0"/>
      </material>
    </visual>
  </link>
  <!-- 脚先（foot_tip）を示す非常に小さなリンク -->
  <link name="limb0_foot_tip">
    <inertial>
      <origin rpy="0 0 0" xyz="0 0 0"/>
      <mass value="0.0001"/>
      <inertia ixx="0.00001" ixy="0.0" ixz="0.0" iyy="0.00001" iyz="0.0" izz="0.00001"/>
    </inertial>
    <!-- X軸（前方向）- 赤色 -->
    <visual name="x_axis">
      <origin rpy="0 1.5707963267948966 0" xyz="0.01 0 0"/>
      <geometry>
        <cylinder length="0.02" radius="0.001"/>
      </geometry>
      <material name="red">
        <color rgba="1.0 0.0 0.0 1.0"/>
      </material>
    </visual>
    <!-- Y軸（右方向）- 緑色 -->
    <visual name="y_axis">
      <origin rpy="1.5707963267948966 0 0" xyz="0 0.01 0"/>
      <geometry>
        <cylinder length="0.02" radius="0.001"/>
      </geometry>
      <material name="green">
        <color rgba="0.0 1.0 0.0 1.0"/>
      </material>
    </visual>
    <!-- Z軸（上方向）- 青色 -->
    <visual name="z_axis">
      <origin rpy="0 0 0" xyz="0 0 0.01"/>
      <geometry>
        <cylinder length="0.02" radius="0.001"/>
      </geometry>
      <material name="blue">
        <color rgba="0.0 0.0 1.0 1.0"/>
      </material>
    </visual>
    <!-- 座標原点 - 白色 -->
    <visual name="origin">
      <origin rpy="0 0 0" xyz="0 0 0"/>
      <geometry>
        <sphere radius="0.003"/>
      </geometry>
      <material name="white">
        <color rgba="1.0 1.0 1.0 1.0"/>
      </material>
    </visual>
  </link>
  <!--joint の定義-->
  <!-- base と motor を固定するジョイント -->
  <joint name="body_motor_fixedjoint_limb0" type="fixed">
    <origin rpy="0 3.141592653589793 4.71238898038469" xyz="0.095 0.0 -0.02"/>
    <parent link="body_link"/>
    <child link="motor0"/>
  </joint>
  <!-- motor と leg_coxa　をジョイント-->
  <joint name="limb0_joint1" type="continuous">
    <origin rpy="0 0 3.141592653589793" xyz="0 0 0.05"/>
    <parent link="motor0"/>
    <child link="limb0_link2"/>
    <axis xyz="0.0 0.0 1.0"/>
  </joint>
  <!-- leg_coxa と leg_fumer　をジョイント-->
  <joint name="limb0_joint2" type="continuous">
    <origin rpy="0 1.5707963267948966 0" xyz="0.0 -0.0145 0"/>
    <parent link="limb0_link2"/>
    <child link="limb0_link4"/>
    <axis xyz="0.0 -1.0 0.0"/>
  </joint>
  <!-- leg_fumer と leg_tibia　をジョイント-->
  <joint name="limb0_joint3" type="continuous">
    <origin rpy="0 0 0" xyz="-0.105 0.0 0"/>
    <parent link="limb0_link4"/>
    <child link="limb0_link6"/>
    <axis xyz="0.0 1.0 0.0"/>
  </joint>
  <!-- tibiaリンクと脚先を接続する固定ジョイント -->
  <joint name="limb0_foot_joint" type="fixed">
    <!-- tibiaのSTLモデルの先端までの距離を設定 -->
    <origin rpy="-1.5707963267948966 0 -1.5707963267948966" xyz="-0.103 0.0205 -0.00205"/>
    <parent link="limb0_link6"/>
    <child link="limb0_foot_tip"/>
  </joint>
  <!-- トランスミッション -->
  <transmission name="trans0_1">
    <type>transmission_interface/SimpleTransmission</type>
    <joint name="limb0_joint1">
      <hardwareInterface>hardware_interface/EffortJointInterface</hardwareInterface>
    </joint>
    <actuator name="motor0_1">
      <hardwareInterface>hardware_interface/EffortJointInterface</hardwareInterface>
      <mechanicalReduction>1</mechanicalReduction>
    </actuator>
  </transmission>
  <transmission name="trans0_2">
    <type>transmission_interface/SimpleTransmission</type>
    <joint name="limb0_joint2">
      <hardwareInterface>hardware_interface/EffortJointInterface</hardwareInterface>
    </joint>
    <actuator name="motor0_2">
      <hardwareInterface>hardware_interface/EffortJointInterface</hardwareInterface>
      <mechanicalReduction>1</mechanicalReduction>
    </actuator>
  </transmission>
  <transmission name="trans0_3">
    <type>transmission_interface/SimpleTransmission</type>
    <joint name="limb0_joint3">
      <hardwareInterface>hardware_interface/EffortJointInterface</hardwareInterface>
    </joint>
    <actuator name="motor0_3">
      <hardwareInterface>hardware_interface/EffortJointInterface</hardwareInterface>
      <mechanicalReduction>1</mechanicalReduction>
    </actuator>
  </transmission>
  <!-- モーターの設定 -->
  <link name="motor1">
    <!--  物理シミュレーションのための質量特性を定義 -->
    <inertial>
      <!-- 慣性フレームの位置と向き -->
      <origin rpy="0 0 0" xyz="0 0 0"/>
      <!-- 部品の質量（kg単位） -->
      <mass value="0.125"/>
      <!--  慣性テンソル（物体の回転に対する抵抗を定義する行列） -->
      <!-- ixx, iyy, izz - 各軸周りの慣性モーメント -->
      <!-- ixy, iyz, ixz - 慣性乗積（オフ対角成分） -->
      <inertia ixx="0.1" ixy="0.0" ixz="0.0" iyy="0.1" iyz="0.0" izz="0.1"/>
    </inertial>
    <!-- 視覚・表示の設定 -->
    <visual>
      <!-- 表示モデルの位置と向き -->
      <origin rpy="0 0 0" xyz="0 0.005 0"/>
      <!--  形状を定義 -->
      <geometry>
        <mesh filename="package://dual_leg_controller/model/meshes/motor.stl" scale="0.001 0.001 0.001"/>
      </geometry>
      <material name="steel_satin"/>
    </visual>
    <!-- 衝突検出形状 (物理シミュレーション用)の設定 -->
    <collision>
      <!-- 衝突モデルの位置と向き -->
      <origin rpy="0 0 0" xyz="0 0.005 0"/>
      <!--  形状を定義 -->
      <geometry>
        <mesh filename="package://dual_leg_controller/model/meshes/motor.stl" scale="0.001 0.001 0.001"/>
      </geometry>
    </collision>
  </link>
  <!-- coxa_motor と femur_motor をつなぐリンク(leg_coxa)の定義  -->
  <link name="limb1_link2">
    <!--  物理シミュレーションのための質量特性を定義 -->
    <inertial>
      <origin rpy="0 0 0" xyz="0 0 0"/>
      <mass value="0.125"/>
      <inertia ixx="0.1" ixy="0.0" ixz="0.0" iyy="0.1" iyz="0.0" izz="0.1"/>
    </inertial>
    <!-- 視覚・表示の設定 -->
    <visual>
      <origin rpy="0 -1.5707963267948966 0" xyz="0 0 -0.045"/>
      <geometry>
        <mesh filename="package://dual_leg_controller/model/meshes/link1_1.stl" scale="0.001 0.001 0.001"/>
      </geometry>
      <material name="steel_satin"/>
    </visual>
    <!-- 衝突検出形状 (物理シミュレーション用)の設定 -->
    <collision>
      <origin rpy="0 -1.5707963267948966 0" xyz="0 0 -0.045"/>
      <geometry>
        <mesh filename="package://dual_leg_controller/model/meshes/link1_1.stl" scale="0.001 0.001 0.001"/>
      </geometry>
    </collision>
  </link>
  <!-- femur_motor と tibia_motor をつなぐリンク(leg_fumer)の定義  -->
  <link name="limb1_link4">
    <inertial>
      <mass value="0.125"/>
      <inertia ixx="0.1" ixy="0.0" ixz="0.0" iyy="0.1" iyz="0.0" izz="0.1"/>
    </inertial>
    <visual>
      <origin rpy="0 3.141592653589793 -1.5707963267948966" xyz="0.05 -0.055 0"/>
      <geometry>
        <mesh filename="package://dual_leg_controller/model/meshes/link2_1.stl" scale="0.001 0.001 0.001"/>
      </geometry>
      <material name="steel_satin"/>
    </visual>
    <collision>
      <origin rpy="0 3.141592653589793 -1.5707963267948966" xyz="0.05 -0.055 0"/>
      <geometry>
        <mesh filename="package://dual_leg_controller/model/meshes/link2_1.stl" scale="0.001 0.001 0.001"/>
      </geometry>
    </collision>
  </link>
  <link name="limb1_link6">
    <inertial>
      <origin rpy="0 0 0" xyz="0 0 0"/>
      <mass value="0.125"/>
      <inertia ixx="0.1" ixy="0.0" ixz="0.0" iyy="0.1" iyz="0.0" izz="0.1"/>
    </inertial>
    <visual>
      <origin rpy="3.141592653589793 0 3.141592653589793" xyz="0.055 0.038 0"/>
      <geometry>
        <mesh filename="package://dual_leg_controller/model/meshes/link3_1.stl" scale="0.001 0.001 0.001"/>
      </geometry>
      <material name="steel_satin"/>
    </visual>
    <collision>
      <origin rpy="3.141592653589793 0 3.141592653589793" xyz="0.055 0.038 0"/>
      <geometry>
        <mesh filename="package://dual_leg_controller/model/meshes/link3_1.stl" scale="0.001 0.001 0.001"/>
      </geometry>
    </collision>
    <!-- 座標系確認用の軸表示を追加 -->
    <visual name="debug_x_axis">
      <origin rpy="0 1.5707963267948966 0" xyz="0.02 0 0"/>
      <geometry>
        <cylinder length="0.04" radius="0.002"/>
      </geometry>
      <material name="debug_red">
        <color rgba="1.0 0.0 0.0 1.0"/>
      </material>
    </visual>
    <visual name="debug_y_axis">
      <origin rpy="1.5707963267948966 0 0" xyz="0 0.02 0"/>
      <geometry>
        <cylinder length="0.04" radius="0.002"/>
      </geometry>
      <material name="debug_green">
        <color rgba="0.0 1.0 0.0 1.0"/>
      </material>
    </visual>
    <visual name="debug_z_axis">
      <origin rpy="0 0 0" xyz="0 0 0.02"/>
      <geometry>
        <cylinder length="0.04" radius="0.002"/>
      </geometry>
      <material name="debug_blue">
        <color rgba="0.0 0.0 1.0 1.0"/>
      </material>
    </visual>
  </link>
  <!-- 脚先（foot_tip）を示す非常に小さなリンク -->
  <link name="limb1_foot_tip">
    <inertial>
      <origin rpy="0 0 0" xyz="0 0 0"/>
      <mass value="0.0001"/>
      <inertia ixx="0.00001" ixy="0.0" ixz="0.0" iyy="0.00001" iyz="0.0" izz="0.00001"/>
    </inertial>
    <!-- X軸（前方向）- 赤色 -->
    <visual name="x_axis">
      <origin rpy="0 1.5707963267948966 0" xyz="0.01 0 0"/>
      <geometry>
        <cylinder length="0.02" radius="0.001"/>
      </geometry>
      <material name="red">
        <color rgba="1.0 0.0 0.0 1.0"/>
      </material>
    </visual>
    <!-- Y軸（右方向）- 緑色 -->
    <visual name="y_axis">
      <origin rpy="1.5707963267948966 0 0" xyz="0 0.01 0"/>
      <geometry>
        <cylinder length="0.02" radius="0.001"/>
      </geometry>
      <material name="green">
        <color rgba="0.0 1.0 0.0 1.0"/>
      </material>
    </visual>
    <!-- Z軸（上方向）- 青色 -->
    <visual name="z_axis">
      <origin rpy="0 0 0" xyz="0 0 0.01"/>
      <geometry>
        <cylinder length="0.02" radius="0.001"/>
      </geometry>
      <material name="blue">
        <color rgba="0.0 0.0 1.0 1.0"/>
      </material>
    </visual>
    <!-- 座標原点 - 白色 -->
    <visual name="origin">
      <origin rpy="0 0 0" xyz="0 0 0"/>
      <geometry>
        <sphere radius="0.003"/>
      </geometry>
      <material name="white">
        <color rgba="1.0 1.0 1.0 1.0"/>
      </material>
    </visual>
  </link>
  <!--joint の定義-->
  <!-- base と motor を固定するジョイント -->
  <joint name="body_motor_fixedjoint_limb1" type="fixed">
    <origin rpy="0 3.141592653589793 5.759586531581287" xyz="0.047500000000000014 0.08227241335952167 -0.02"/>
    <parent link="body_link"/>
    <child link="motor1"/>
  </joint>
  <!-- motor と leg_coxa　をジョイント-->
  <joint name="limb1_joint1" type="continuous">
    <origin rpy="0 0 3.141592653589793" xyz="0 0 0.05"/>
    <parent link="motor1"/>
    <child link="limb1_link2"/>
    <axis xyz="0.0 0.0 1.0"/>
  </joint>
  <!-- leg_coxa と leg_fumer　をジョイント-->
  <joint name="limb1_joint2" type="continuous">
    <origin rpy="0 1.5707963267948966 0" xyz="0.0 -0.0145 0"/>
    <parent link="limb1_link2"/>
    <child link="limb1_link4"/>
    <axis xyz="0.0 -1.0 0.0"/>
  </joint>
  <!-- leg_fumer と leg_tibia　をジョイント-->
  <joint name="limb1_joint3" type="continuous">
    <origin rpy="0 0 0" xyz="-0.105 0.0 0"/>
    <parent link="limb1_link4"/>
    <child link="limb1_link6"/>
    <axis xyz="0.0 1.0 0.0"/>
  </joint>
  <!-- tibiaリンクと脚先を接続する固定ジョイント -->
  <joint name="limb1_foot_joint" type="fixed">
    <!-- tibiaのSTLモデルの先端までの距離を設定 -->
    <origin rpy="-1.5707963267948966 0 -1.5707963267948966" xyz="-0.103 0.0205 -0.00205"/>
    <parent link="limb1_link6"/>
    <child link="limb1_foot_tip"/>
  </joint>
  <!-- トランスミッション -->
  <transmission name="trans1_1">
    <type>transmission_interface/SimpleTransmission</type>
    <joint name="limb1_joint1">
      <hardwareInterface>hardware_interface/EffortJointInterface</hardwareInterface>
    </joint>
    <actuator name="motor1_1">
      <hardwareInterface>hardware_interface/EffortJointInterface</hardwareInterface>
      <mechanicalReduction>1</mechanicalReduction>
    </actuator>
  </transmission>
  <transmission name="trans1_2">
    <type>transmission_interface/SimpleTransmission</type>
    <joint name="limb1_joint2">
      <hardwareInterface>hardware_interface/EffortJointInterface</hardwareInterface>
    </joint>
    <actuator name="motor1_2">
      <hardwareInterface>hardware_interface/EffortJointInterface</hardwareInterface>
      <mechanicalReduction>1</mechanicalReduction>
    </actuator>
  </transmission>
  <transmission name="trans1_3">
    <type>transmission_interface/SimpleTransmission</type>
    <joint name="limb1_joint3">
      <hardwareInterface>hardware_interface/EffortJointInterface</hardwareInterface>
    </joint>
    <actuator name="motor1_3">
      <hardwareInterface>hardware_interface/EffortJointInterface</hardwareInterface>
      <mechanicalReduction>1</mechanicalReduction>
    </actuator>
  </transmission>
  <!-- モーターの設定 -->
  <link name="motor2">
    <!--  物理シミュレーションのための質量特性を定義 -->
    <inertial>
      <!-- 慣性フレームの位置と向き -->
      <origin rpy="0 0 0" xyz="0 0 0"/>
      <!-- 部品の質量（kg単位） -->
      <mass value="0.125"/>
      <!--  慣性テンソル（物体の回転に対する抵抗を定義する行列） -->
      <!-- ixx, iyy, izz - 各軸周りの慣性モーメント -->
      <!-- ixy, iyz, ixz - 慣性乗積（オフ対角成分） -->
      <inertia ixx="0.1" ixy="0.0" ixz="0.0" iyy="0.1" iyz="0.0" izz="0.1"/>
    </inertial>
    <!-- 視覚・表示の設定 -->
    <visual>
      <!-- 表示モデルの位置と向き -->
      <origin rpy="0 0 0" xyz="0 0.005 0"/>
      <!--  形状を定義 -->
      <geometry>
        <mesh filename="package://dual_leg_controller/model/meshes/motor.stl" scale="0.001 0.001 0.001"/>
      </geometry>
      <material name="steel_satin"/>
    </visual>
    <!-- 衝突検出形状 (物理シミュレーション用)の設定 -->
    <collision>
      <!-- 衝突モデルの位置と向き -->
      <origin rpy="0 0 0" xyz="0 0.005 0"/>
      <!--  形状を定義 -->
      <geometry>
        <mesh filename="package://dual_leg_controller/model/meshes/motor.stl" scale="0.001 0.001 0.001"/>
      </geometry>
    </collision>
  </link>
  <!-- coxa_motor と femur_motor をつなぐリンク(leg_coxa)の定義  -->
  <link name="limb2_link2">
    <!--  物理シミュレーションのための質量特性を定義 -->
    <inertial>
      <origin rpy="0 0 0" xyz="0 0 0"/>
      <mass value="0.125"/>
      <inertia ixx="0.1" ixy="0.0" ixz="0.0" iyy="0.1" iyz="0.0" izz="0.1"/>
    </inertial>
    <!-- 視覚・表示の設定 -->
    <visual>
      <origin rpy="0 -1.5707963267948966 0" xyz="0 0 -0.045"/>
      <geometry>
        <mesh filename="package://dual_leg_controller/model/meshes/link1_1.stl" scale="0.001 0.001 0.001"/>
      </geometry>
      <material name="steel_satin"/>
    </visual>
    <!-- 衝突検出形状 (物理シミュレーション用)の設定 -->
    <collision>
      <origin rpy="0 -1.5707963267948966 0" xyz="0 0 -0.045"/>
      <geometry>
        <mesh filename="package://dual_leg_controller/model/meshes/link1_1.stl" scale="0.001 0.001 0.001"/>
      </geometry>
    </collision>
  </link>
  <!-- femur_motor と tibia_motor をつなぐリンク(leg_fumer)の定義  -->
  <link name="limb2_link4">
    <inertial>
      <mass value="0.125"/>
      <inertia ixx="0.1" ixy="0.0" ixz="0.0" iyy="0.1" iyz="0.0" izz="0.1"/>
    </inertial>
    <visual>
      <origin rpy="0 3.141592653589793 -1.5707963267948966" xyz="0.05 -0.055 0"/>
      <geometry>
        <mesh filename="package://dual_leg_controller/model/meshes/link2_1.stl" scale="0.001 0.001 0.001"/>
      </geometry>
      <material name="steel_satin"/>
    </visual>
    <collision>
      <origin rpy="0 3.141592653589793 -1.5707963267948966" xyz="0.05 -0.055 0"/>
      <geometry>
        <mesh filename="package://dual_leg_controller/model/meshes/link2_1.stl" scale="0.001 0.001 0.001"/>
      </geometry>
    </collision>
  </link>
  <link name="limb2_link6">
    <inertial>
      <origin rpy="0 0 0" xyz="0 0 0"/>
      <mass value="0.125"/>
      <inertia ixx="0.1" ixy="0.0" ixz="0.0" iyy="0.1" iyz="0.0" izz="0.1"/>
    </inertial>
    <visual>
      <origin rpy="3.141592653589793 0 3.141592653589793" xyz="0.055 0.038 0"/>
      <geometry>
        <mesh filename="package://dual_leg_controller/model/meshes/link3_1.stl" scale="0.001 0.001 0.001"/>
      </geometry>
      <material name="steel_satin"/>
    </visual>
    <collision>
      <origin rpy="3.141592653589793 0 3.141592653589793" xyz="0.055 0.038 0"/>
      <geometry>
        <mesh filename="package://dual_leg_controller/model/meshes/link3_1.stl" scale="0.001 0.001 0.001"/>
      </geometry>
    </collision>
    <!-- 座標系確認用の軸表示を追加 -->
    <visual name="debug_x_axis">
      <origin rpy="0 1.5707963267948966 0" xyz="0.02 0 0"/>
      <geometry>
        <cylinder length="0.04" radius="0.002"/>
      </geometry>
      <material name="debug_red">
        <color rgba="1.0 0.0 0.0 1.0"/>
      </material>
    </visual>
    <visual name="debug_y_axis">
      <origin rpy="1.5707963267948966 0 0" xyz="0 0.02 0"/>
      <geometry>
        <cylinder length="0.04" radius="0.002"/>
      </geometry>
      <material name="debug_green">
        <color rgba="0.0 1.0 0.0 1.0"/>
      </material>
    </visual>
    <visual name="debug_z_axis">
      <origin rpy="0 0 0" xyz="0 0 0.02"/>
      <geometry>
        <cylinder length="0.04" radius="0.002"/>
      </geometry>
      <material name="debug_blue">
        <color rgba="0.0 0.0 1.0 1.0"/>
      </material>
    </visual>
  </link>
  <!-- 脚先（foot_tip）を示す非常に小さなリンク -->
  <link name="limb2_foot_tip">
    <inertial>
      <origin rpy="0 0 0" xyz="0 0 0"/>
      <mass value="0.0001"/>
      <inertia ixx="0.00001" ixy="0.0" ixz="0.0" iyy="0.00001" iyz="0.0" izz="0.00001"/>
    </inertial>
    <!-- X軸（前方向）- 赤色 -->
    <visual name="x_axis">
      <origin rpy="0 1.5707963267948966 0" xyz="0.01 0 0"/>
      <geometry>
        <cylinder length="0.02" radius="0.001"/>
      </geometry>
      <material name="red">
        <color rgba="1.0 0.0 0.0 1.0"/>
      </material>
    </visual>
    <!-- Y軸（右方向）- 緑色 -->
    <visual name="y_axis">
      <origin rpy="1.5707963267948966 0 0" xyz="0 0.01 0"/>
      <geometry>
        <cylinder length="0.02" radius="0.001"/>
      </geometry>
      <material name="green">
        <color rgba="0.0 1.0 0.0 1.0"/>
      </material>
    </visual>
    <!-- Z軸（上方向）- 青色 -->
    <visual name="z_axis">
      <origin rpy="0 0 0" xyz="0 0 0.01"/>
      <geometry>
        <cylinder length="0.02" radius="0.001"/>
      </geometry>
      <material name="blue">
        <color rgba="0.0 0.0 1.0 1.0"/>
      </material>
    </visual>
    <!-- 座標原点 - 白色 -->
    <visual name="origin">
      <origin rpy="0 0 0" xyz="0 0 0"/>
      <geometry>
        <sphere radius="0.003"/>
      </geometry>
      <material name="white">
        <color rgba="1.0 1.0 1.0 1.0"/>
      </material>
    </visual>
  </link>
  <!--joint の定義-->
  <!-- base と motor を固定するジョイント -->
  <joint name="body_motor_fixedjoint_limb2" type="fixed">
    <origin rpy="0 3.141592653589793 6.806784082777885" xyz="-0.04749999999999998 0.08227241335952168 -0.02"/>
    <parent link="body_link"/>
    <child link="motor2"/>
  </joint>
  <!-- motor と leg_coxa　をジョイント-->
  <joint name="limb2_joint1" type="continuous">
    <origin rpy="0 0 3.141592653589793" xyz="0 0 0.05"/>
    <parent link="motor2"/>
    <child link="limb2_link2"/>
    <axis xyz="0.0 0.0 1.0"/>
  </joint>
  <!-- leg_coxa と leg_fumer　をジョイント-->
  <joint name="limb2_joint2" type="continuous">
    <origin rpy="0 1.5707963267948966 0" xyz="0.0 -0.0145 0"/>
    <parent link="limb2_link2"/>
    <child link="limb2_link4"/>
    <axis xyz="0.0 -1.0 0.0"/>
  </joint>
  <!-- leg_fumer と leg_tibia　をジョイント-->
  <joint name="limb2_joint3" type="continuous">
    <origin rpy="0 0 0" xyz="-0.105 0.0 0"/>
    <parent link="limb2_link4"/>
    <child link="limb2_link6"/>
    <axis xyz="0.0 1.0 0.0"/>
  </joint>
  <!-- tibiaリンクと脚先を接続する固定ジョイント -->
  <joint name="limb2_foot_joint" type="fixed">
    <!-- tibiaのSTLモデルの先端までの距離を設定 -->
    <origin rpy="-1.5707963267948966 0 -1.5707963267948966" xyz="-0.103 0.0205 -0.00205"/>
    <parent link="limb2_link6"/>
    <child link="limb2_foot_tip"/>
  </joint>
  <!-- トランスミッション -->
  <transmission name="trans2_1">
    <type>transmission_interface/SimpleTransmission</type>
    <joint name="limb2_joint1">
      <hardwareInterface>hardware_interface/EffortJointInterface</hardwareInterface>
    </joint>
    <actuator name="motor2_1">
      <hardwareInterface>hardware_interface/EffortJointInterface</hardwareInterface>
      <mechanicalReduction>1</mechanicalReduction>
    </actuator>
  </transmission>
  <transmission name="trans2_2">
    <type>transmission_interface/SimpleTransmission</type>
    <joint name="limb2_joint2">
      <hardwareInterface>hardware_interface/EffortJointInterface</hardwareInterface>
    </joint>
    <actuator name="motor2_2">
      <hardwareInterface>hardware_interface/EffortJointInterface</hardwareInterface>
      <mechanicalReduction>1</mechanicalReduction>
    </actuator>
  </transmission>
  <transmission name="trans2_3">
    <type>transmission_interface/SimpleTransmission</type>
    <joint name="limb2_joint3">
      <hardwareInterface>hardware_interface/EffortJointInterface</hardwareInterface>
    </joint>
    <actuator name="motor2_3">
      <hardwareInterface>hardware_interface/EffortJointInterface</hardwareInterface>
      <mechanicalReduction>1</mechanicalReduction>
    </actuator>
  </transmission>
  <!-- モーターの設定 -->
  <link name="motor3">
    <!--  物理シミュレーションのための質量特性を定義 -->
    <inertial>
      <!-- 慣性フレームの位置と向き -->
      <origin rpy="0 0 0" xyz="0 0 0"/>
      <!-- 部品の質量（kg単位） -->
      <mass value="0.125"/>
      <!--  慣性テンソル（物体の回転に対する抵抗を定義する行列） -->
      <!-- ixx, iyy, izz - 各軸周りの慣性モーメント -->
      <!-- ixy, iyz, ixz - 慣性乗積（オフ対角成分） -->
      <inertia ixx="0.1" ixy="0.0" ixz="0.0" iyy="0.1" iyz="0.0" izz="0.1"/>
    </inertial>
    <!-- 視覚・表示の設定 -->
    <visual>
      <!-- 表示モデルの位置と向き -->
      <origin rpy="0 0 0" xyz="0 0.005 0"/>
      <!--  形状を定義 -->
      <geometry>
        <mesh filename="package://dual_leg_controller/model/meshes/motor.stl" scale="0.001 0.001 0.001"/>
      </geometry>
      <material name="steel_satin"/>
    </visual>
    <!-- 衝突検出形状 (物理シミュレーション用)の設定 -->
    <collision>
      <!-- 衝突モデルの位置と向き -->
      <origin rpy="0 0 0" xyz="0 0.005 0"/>
      <!--  形状を定義 -->
      <geometry>
        <mesh filename="package://dual_leg_controller/model/meshes/motor.stl" scale="0.001 0.001 0.001"/>
      </geometry>
    </collision>
  </link>
  <!-- coxa_motor と femur_motor をつなぐリンク(leg_coxa)の定義  -->
  <link name="limb3_link2">
    <!--  物理シミュレーションのための質量特性を定義 -->
    <inertial>
      <origin rpy="0 0 0" xyz="0 0 0"/>
      <mass value="0.125"/>
      <inertia ixx="0.1" ixy="0.0" ixz="0.0" iyy="0.1" iyz="0.0" izz="0.1"/>
    </inertial>
    <!-- 視覚・表示の設定 -->
    <visual>
      <origin rpy="0 -1.5707963267948966 0" xyz="0 0 -0.045"/>
      <geometry>
        <mesh filename="package://dual_leg_controller/model/meshes/link1_1.stl" scale="0.001 0.001 0.001"/>
      </geometry>
      <material name="steel_satin"/>
    </visual>
    <!-- 衝突検出形状 (物理シミュレーション用)の設定 -->
    <collision>
      <origin rpy="0 -1.5707963267948966 0" xyz="0 0 -0.045"/>
      <geometry>
        <mesh filename="package://dual_leg_controller/model/meshes/link1_1.stl" scale="0.001 0.001 0.001"/>
      </geometry>
    </collision>
  </link>
  <!-- femur_motor と tibia_motor をつなぐリンク(leg_fumer)の定義  -->
  <link name="limb3_link4">
    <inertial>
      <mass value="0.125"/>
      <inertia ixx="0.1" ixy="0.0" ixz="0.0" iyy="0.1" iyz="0.0" izz="0.1"/>
    </inertial>
    <visual>
      <origin rpy="0 3.141592653589793 -1.5707963267948966" xyz="0.05 -0.055 0"/>
      <geometry>
        <mesh filename="package://dual_leg_controller/model/meshes/link2_1.stl" scale="0.001 0.001 0.001"/>
      </geometry>
      <material name="steel_satin"/>
    </visual>
    <collision>
      <origin rpy="0 3.141592653589793 -1.5707963267948966" xyz="0.05 -0.055 0"/>
      <geometry>
        <mesh filename="package://dual_leg_controller/model/meshes/link2_1.stl" scale="0.001 0.001 0.001"/>
      </geometry>
    </collision>
  </link>
  <link name="limb3_link6">
    <inertial>
      <origin rpy="0 0 0" xyz="0 0 0"/>
      <mass value="0.125"/>
      <inertia ixx="0.1" ixy="0.0" ixz="0.0" iyy="0.1" iyz="0.0" izz="0.1"/>
    </inertial>
    <visual>
      <origin rpy="3.141592653589793 0 3.141592653589793" xyz="0.055 0.038 0"/>
      <geometry>
        <mesh filename="package://dual_leg_controller/model/meshes/link3_1.stl" scale="0.001 0.001 0.001"/>
      </geometry>
      <material name="steel_satin"/>
    </visual>
    <collision>
      <origin rpy="3.141592653589793 0 3.141592653589793" xyz="0.055 0.038 0"/>
      <geometry>
        <mesh filename="package://dual_leg_controller/model/meshes/link3_1.stl" scale="0.001 0.001 0.001"/>
      </geometry>
    </collision>
    <!-- 座標系確認用の軸表示を追加 -->
    <visual name="debug_x_axis">
      <origin rpy="0 1.5707963267948966 0" xyz="0.02 0 0"/>
      <geometry>
        <cylinder length="0.04" radius="0.002"/>
      </geometry>
      <material name="debug_red">
        <color rgba="1.0 0.0 0.0 1.0"/>
      </material>
    </visual>
    <visual name="debug_y_axis">
      <origin rpy="1.5707963267948966 0 0" xyz="0 0.02 0"/>
      <geometry>
        <cylinder length="0.04" radius="0.002"/>
      </geometry>
      <material name="debug_green">
        <color rgba="0.0 1.0 0.0 1.0"/>
      </material>
    </visual>
    <visual name="debug_z_axis">
      <origin rpy="0 0 0" xyz="0 0 0.02"/>
      <geometry>
        <cylinder length="0.04" radius="0.002"/>
      </geometry>
      <material name="debug_blue">
        <color rgba="0.0 0.0 1.0 1.0"/>
      </material>
    </visual>
  </link>
  <!-- 脚先（foot_tip）を示す非常に小さなリンク -->
  <link name="limb3_foot_tip">
    <inertial>
      <origin rpy="0 0 0" xyz="0 0 0"/>
      <mass value="0.0001"/>
      <inertia ixx="0.00001" ixy="0.0" ixz="0.0" iyy="0.00001" iyz="0.0" izz="0.00001"/>
    </inertial>
    <!-- X軸（前方向）- 赤色 -->
    <visual name="x_axis">
      <origin rpy="0 1.5707963267948966 0" xyz="0.01 0 0"/>
      <geometry>
        <cylinder length="0.02" radius="0.001"/>
      </geometry>
      <material name="red">
        <color rgba="1.0 0.0 0.0 1.0"/>
      </material>
    </visual>
    <!-- Y軸（右方向）- 緑色 -->
    <visual name="y_axis">
      <origin rpy="1.5707963267948966 0 0" xyz="0 0.01 0"/>
      <geometry>
        <cylinder length="0.02" radius="0.001"/>
      </geometry>
      <material name="green">
        <color rgba="0.0 1.0 0.0 1.0"/>
      </material>
    </visual>
    <!-- Z軸（上方向）- 青色 -->
    <visual name="z_axis">
      <origin rpy="0 0 0" xyz="0 0 0.01"/>
      <geometry>
        <cylinder length="0.02" radius="0.001"/>
      </geometry>
      <material name="blue">
        <color rgba="0.0 0.0 1.0 1.0"/>
      </material>
    </visual>
    <!-- 座標原点 - 白色 -->
    <visual name="origin">
      <origin rpy="0 0 0" xyz="0 0 0"/>
      <geometry>
        <sphere radius="0.003"/>
      </geometry>
      <material name="white">
        <color rgba="1.0 1.0 1.0 1.0"/>
      </material>
    </visual>
  </link>
  <!--joint の定義-->
  <!-- base と motor を固定するジョイント -->
  <joint name="body_motor_fixedjoint_limb3" type="fixed">
    <origin rpy="0 3.141592653589793 7.853981633974483" xyz="-0.095 1.1634144591899856e-17 -0.02"/>
    <parent link="body_link"/>
    <child link="motor3"/>
  </joint>
  <!-- motor と leg_coxa　をジョイント-->
  <joint name="limb3_joint1" type="continuous">
    <origin rpy="0 0 3.141592653589793" xyz="0 0 0.05"/>
    <parent link="motor3"/>
    <child link="limb3_link2"/>
    <axis xyz="0.0 0.0 1.0"/>
  </joint>
  <!-- leg_coxa と leg_fumer　をジョイント-->
  <joint name="limb3_joint2" type="continuous">
    <origin rpy="0 1.5707963267948966 0" xyz="0.0 -0.0145 0"/>
    <parent link="limb3_link2"/>
    <child link="limb3_link4"/>
    <axis xyz="0.0 -1.0 0.0"/>
  </joint>
  <!-- leg_fumer と leg_tibia　をジョイント-->
  <joint name="limb3_joint3" type="continuous">
    <origin rpy="0 0 0" xyz="-0.105 0.0 0"/>
    <parent link="limb3_link4"/>
    <child link="limb3_link6"/>
    <axis xyz="0.0 1.0 0.0"/>
  </joint>
  <!-- tibiaリンクと脚先を接続する固定ジョイント -->
  <joint name="limb3_foot_joint" type="fixed">
    <!-- tibiaのSTLモデルの先端までの距離を設定 -->
    <origin rpy="-1.5707963267948966 0 -1.5707963267948966" xyz="-0.103 0.0205 -0.00205"/>
    <parent link="limb3_link6"/>
    <child link="limb3_foot_tip"/>
  </joint>
  <!-- トランスミッション -->
  <transmission name="trans3_1">
    <type>transmission_interface/SimpleTransmission</type>
    <joint name="limb3_joint1">
      <hardwareInterface>hardware_interface/EffortJointInterface</hardwareInterface>
    </joint>
    <actuator name="motor3_1">
      <hardwareInterface>hardware_interface/EffortJointInterface</hardwareInterface>
      <mechanicalReduction>1</mechanicalReduction>
    </actuator>
  </transmission>
  <transmission name="trans3_2">
    <type>transmission_interface/SimpleTransmission</type>
    <joint name="limb3_joint2">
      <hardwareInterface>hardware_interface/EffortJointInterface</hardwareInterface>
    </joint>
    <actuator name="motor3_2">
      <hardwareInterface>hardware_interface/EffortJointInterface</hardwareInterface>
      <mechanicalReduction>1</mechanicalReduction>
    </actuator>
  </transmission>
  <transmission name="trans3_3">
    <type>transmission_interface/SimpleTransmission</type>
    <joint name="limb3_joint3">
      <hardwareInterface>hardware_interface/EffortJointInterface</hardwareInterface>
    </joint>
    <actuator name="motor3_3">
      <hardwareInterface>hardware_interface/EffortJointInterface</hardwareInterface>
      <mechanicalReduction>1</mechanicalReduction>
    </actuator>
  </transmission>
  <!-- モーターの設定 -->
  <link name="motor4">
    <!--  物理シミュレーションのための質量特性を定義 -->
    <inertial>
      <!-- 慣性フレームの位置と向き -->
      <origin rpy="0 0 0" xyz="0 0 0"/>
      <!-- 部品の質量（kg単位） -->
      <mass value="0.125"/>
      <!--  慣性テンソル（物体の回転に対する抵抗を定義する行列） -->
      <!-- ixx, iyy, izz - 各軸周りの慣性モーメント -->
      <!-- ixy, iyz, ixz - 慣性乗積（オフ対角成分） -->
      <inertia ixx="0.1" ixy="0.0" ixz="0.0" iyy="0.1" iyz="0.0" izz="0.1"/>
    </inertial>
    <!-- 視覚・表示の設定 -->
    <visual>
      <!-- 表示モデルの位置と向き -->
      <origin rpy="0 0 0" xyz="0 0.005 0"/>
      <!--  形状を定義 -->
      <geometry>
        <mesh filename="package://dual_leg_controller/model/meshes/motor.stl" scale="0.001 0.001 0.001"/>
      </geometry>
      <material name="steel_satin"/>
    </visual>
    <!-- 衝突検出形状 (物理シミュレーション用)の設定 -->
    <collision>
      <!-- 衝突モデルの位置と向き -->
      <origin rpy="0 0 0" xyz="0 0.005 0"/>
      <!--  形状を定義 -->
      <geometry>
        <mesh filename="package://dual_leg_controller/model/meshes/motor.stl" scale="0.001 0.001 0.001"/>
      </geometry>
    </collision>
  </link>
  <!-- coxa_motor と femur_motor をつなぐリンク(leg_coxa)の定義  -->
  <link name="limb4_link2">
    <!--  物理シミュレーションのための質量特性を定義 -->
    <inertial>
      <origin rpy="0 0 0" xyz="0 0 0"/>
      <mass value="0.125"/>
      <inertia ixx="0.1" ixy="0.0" ixz="0.0" iyy="0.1" iyz="0.0" izz="0.1"/>
    </inertial>
    <!-- 視覚・表示の設定 -->
    <visual>
      <origin rpy="0 -1.5707963267948966 0" xyz="0 0 -0.045"/>
      <geometry>
        <mesh filename="package://dual_leg_controller/model/meshes/link1_1.stl" scale="0.001 0.001 0.001"/>
      </geometry>
      <material name="steel_satin"/>
    </visual>
    <!-- 衝突検出形状 (物理シミュレーション用)の設定 -->
    <collision>
      <origin rpy="0 -1.5707963267948966 0" xyz="0 0 -0.045"/>
      <geometry>
        <mesh filename="package://dual_leg_controller/model/meshes/link1_1.stl" scale="0.001 0.001 0.001"/>
      </geometry>
    </collision>
  </link>
  <!-- femur_motor と tibia_motor をつなぐリンク(leg_fumer)の定義  -->
  <link name="limb4_link4">
    <inertial>
      <mass value="0.125"/>
      <inertia ixx="0.1" ixy="0.0" ixz="0.0" iyy="0.1" iyz="0.0" izz="0.1"/>
    </inertial>
    <visual>
      <origin rpy="0 3.141592653589793 -1.5707963267948966" xyz="0.05 -0.055 0"/>
      <geometry>
        <mesh filename="package://dual_leg_controller/model/meshes/link2_1.stl" scale="0.001 0.001 0.001"/>
      </geometry>
      <material name="steel_satin"/>
    </visual>
    <collision>
      <origin rpy="0 3.141592653589793 -1.5707963267948966" xyz="0.05 -0.055 0"/>
      <geometry>
        <mesh filename="package://dual_leg_controller/model/meshes/link2_1.stl" scale="0.001 0.001 0.001"/>
      </geometry>
    </collision>
  </link>
  <link name="limb4_link6">
    <inertial>
      <origin rpy="0 0 0" xyz="0 0 0"/>
      <mass value="0.125"/>
      <inertia ixx="0.1" ixy="0.0" ixz="0.0" iyy="0.1" iyz="0.0" izz="0.1"/>
    </inertial>
    <visual>
      <origin rpy="3.141592653589793 0 3.141592653589793" xyz="0.055 0.038 0"/>
      <geometry>
        <mesh filename="package://dual_leg_controller/model/meshes/link3_1.stl" scale="0.001 0.001 0.001"/>
      </geometry>
      <material name="steel_satin"/>
    </visual>
    <collision>
      <origin rpy="3.141592653589793 0 3.141592653589793" xyz="0.055 0.038 0"/>
      <geometry>
        <mesh filename="package://dual_leg_controller/model/meshes/link3_1.stl" scale="0.001 0.001 0.001"/>
      </geometry>
    </collision>
    <!-- 座標系確認用の軸表示を追加 -->
    <visual name="debug_x_axis">
      <origin rpy="0 1.5707963267948966 0" xyz="0.02 0 0"/>
      <geometry>
        <cylinder length="0.04" radius="0.002"/>
      </geometry>
      <material name="debug_red">
        <color rgba="1.0 0.0 0.0 1.0"/>
      </material>
    </visual>
    <visual name="debug_y_axis">
      <origin rpy="1.5707963267948966 0 0" xyz="0 0.02 0"/>
      <geometry>
        <cylinder length="0.04" radius="0.002"/>
      </geometry>
      <material name="debug_green">
        <color rgba="0.0 1.0 0.0 1.0"/>
      </material>
    </visual>
    <visual name="debug_z_axis">
      <origin rpy="0 0 0" xyz="0 0 0.02"/>
      <geometry>
        <cylinder length="0.04" radius="0.002"/>
      </geometry>
      <material name="debug_blue">
        <color rgba="0.0 0.0 1.0 1.0"/>
      </material>
    </visual>
  </link>
  <!-- 脚先（foot_tip）を示す非常に小さなリンク -->
  <link name="limb4_foot_tip">
    <inertial>
      <origin rpy="0 0 0" xyz="0 0 0"/>
      <mass value="0.0001"/>
      <inertia ixx="0.00001" ixy="0.0" ixz="0.0" iyy="0.00001" iyz="0.0" izz="0.00001"/>
    </inertial>
    <!-- X軸（前方向）- 赤色 -->
    <visual name="x_axis">
      <origin rpy="0 1.5707963267948966 0" xyz="0.01 0 0"/>
      <geometry>
        <cylinder length="0.02" radius="0.001"/>
      </geometry>
      <material name="red">
        <color rgba="1.0 0.0 0.0 1.0"/>
      </material>
    </visual>
    <!-- Y軸（右方向）- 緑色 -->
    <visual name="y_axis">
      <origin rpy="1.5707963267948966 0 0" xyz="0 0.01 0"/>
      <geometry>
        <cylinder length="0.02" radius="0.001"/>
      </geometry>
      <material name="green">
        <color rgba="0.0 1.0 0.0 1.0"/>
      </material>
    </visual>
    <!-- Z軸（上方向）- 青色 -->
    <visual name="z_axis">
      <origin rpy="0 0 0" xyz="0 0 0.01"/>
      <geometry>
        <cylinder length="0.02" radius="0.001"/>
      </geometry>
      <material name="blue">
        <color rgba="0.0 0.0 1.0 1.0"/>
      </material>
    </visual>
    <!-- 座標原点 - 白色 -->
    <visual name="origin">
      <origin rpy="0 0 0" xyz="0 0 0"/>
      <geometry>
        <sphere radius="0.003"/>
      </geometry>
      <material name="white">
        <color rgba="1.0 1.0 1.0 1.0"/>
      </material>
    </visual>
  </link>
  <!--joint の定義-->
  <!-- base と motor を固定するジョイント -->
  <joint name="body_motor_fixedjoint_limb4" type="fixed">
    <origin rpy="0 3.141592653589793 8.901179185171081" xyz="-0.04750000000000004 -0.08227241335952165 -0.02"/>
    <parent link="body_link"/>
    <child link="motor4"/>
  </joint>
  <!-- motor と leg_coxa　をジョイント-->
  <joint name="limb4_joint1" type="continuous">
    <origin rpy="0 0 3.141592653589793" xyz="0 0 0.05"/>
    <parent link="motor4"/>
    <child link="limb4_link2"/>
    <axis xyz="0.0 0.0 1.0"/>
  </joint>
  <!-- leg_coxa と leg_fumer　をジョイント-->
  <joint name="limb4_joint2" type="continuous">
    <origin rpy="0 1.5707963267948966 0" xyz="0.0 -0.0145 0"/>
    <parent link="limb4_link2"/>
    <child link="limb4_link4"/>
    <axis xyz="0.0 -1.0 0.0"/>
  </joint>
  <!-- leg_fumer と leg_tibia　をジョイント-->
  <joint name="limb4_joint3" type="continuous">
    <origin rpy="0 0 0" xyz="-0.105 0.0 0"/>
    <parent link="limb4_link4"/>
    <child link="limb4_link6"/>
    <axis xyz="0.0 1.0 0.0"/>
  </joint>
  <!-- tibiaリンクと脚先を接続する固定ジョイント -->
  <joint name="limb4_foot_joint" type="fixed">
    <!-- tibiaのSTLモデルの先端までの距離を設定 -->
    <origin rpy="-1.5707963267948966 0 -1.5707963267948966" xyz="-0.103 0.0205 -0.00205"/>
    <parent link="limb4_link6"/>
    <child link="limb4_foot_tip"/>
  </joint>
  <!-- トランスミッション -->
  <transmission name="trans4_1">
    <type>transmission_interface/SimpleTransmission</type>
    <joint name="limb4_joint1">
      <hardwareInterface>hardware_interface/EffortJointInterface</hardwareInterface>
    </joint>
    <actuator name="motor4_1">
      <hardwareInterface>hardware_interface/EffortJointInterface</hardwareInterface>
      <mechanicalReduction>1</mechanicalReduction>
    </actuator>
  </transmission>
  <transmission name="trans4_2">
    <type>transmission_interface/SimpleTransmission</type>
    <joint name="limb4_joint2">
      <hardwareInterface>hardware_interface/EffortJointInterface</hardwareInterface>
    </joint>
    <actuator name="motor4_2">
      <hardwareInterface>hardware_interface/EffortJointInterface</hardwareInterface>
      <mechanicalReduction>1</mechanicalReduction>
    </actuator>
  </transmission>
  <transmission name="trans4_3">
    <type>transmission_interface/SimpleTransmission</type>
    <joint name="limb4_joint3">
      <hardwareInterface>hardware_interface/EffortJointInterface</hardwareInterface>
    </joint>
    <actuator name="motor4_3">
      <hardwareInterface>hardware_interface/EffortJointInterface</hardwareInterface>
      <mechanicalReduction>1</mechanicalReduction>
    </actuator>
  </transmission>
  <!-- モーターの設定 -->
  <link name="motor5">
    <!--  物理シミュレーションのための質量特性を定義 -->
    <inertial>
      <!-- 慣性フレームの位置と向き -->
      <origin rpy="0 0 0" xyz="0 0 0"/>
      <!-- 部品の質量（kg単位） -->
      <mass value="0.125"/>
      <!--  慣性テンソル（物体の回転に対する抵抗を定義する行列） -->
      <!-- ixx, iyy, izz - 各軸周りの慣性モーメント -->
      <!-- ixy, iyz, ixz - 慣性乗積（オフ対角成分） -->
      <inertia ixx="0.1" ixy="0.0" ixz="0.0" iyy="0.1" iyz="0.0" izz="0.1"/>
    </inertial>
    <!-- 視覚・表示の設定 -->
    <visual>
      <!-- 表示モデルの位置と向き -->
      <origin rpy="0 0 0" xyz="0 0.005 0"/>
      <!--  形状を定義 -->
      <geometry>
        <mesh filename="package://dual_leg_controller/model/meshes/motor.stl" scale="0.001 0.001 0.001"/>
      </geometry>
      <material name="steel_satin"/>
    </visual>
    <!-- 衝突検出形状 (物理シミュレーション用)の設定 -->
    <collision>
      <!-- 衝突モデルの位置と向き -->
      <origin rpy="0 0 0" xyz="0 0.005 0"/>
      <!--  形状を定義 -->
      <geometry>
        <mesh filename="package://dual_leg_controller/model/meshes/motor.stl" scale="0.001 0.001 0.001"/>
      </geometry>
    </collision>
  </link>
  <!-- coxa_motor と femur_motor をつなぐリンク(leg_coxa)の定義  -->
  <link name="limb5_link2">
    <!--  物理シミュレーションのための質量特性を定義 -->
    <inertial>
      <origin rpy="0 0 0" xyz="0 0 0"/>
      <mass value="0.125"/>
      <inertia ixx="0.1" ixy="0.0" ixz="0.0" iyy="0.1" iyz="0.0" izz="0.1"/>
    </inertial>
    <!-- 視覚・表示の設定 -->
    <visual>
      <origin rpy="0 -1.5707963267948966 0" xyz="0 0 -0.045"/>
      <geometry>
        <mesh filename="package://dual_leg_controller/model/meshes/link1_1.stl" scale="0.001 0.001 0.001"/>
      </geometry>
      <material name="steel_satin"/>
    </visual>
    <!-- 衝突検出形状 (物理シミュレーション用)の設定 -->
    <collision>
      <origin rpy="0 -1.5707963267948966 0" xyz="0 0 -0.045"/>
      <geometry>
        <mesh filename="package://dual_leg_controller/model/meshes/link1_1.stl" scale="0.001 0.001 0.001"/>
      </geometry>
    </collision>
  </link>
  <!-- femur_motor と tibia_motor をつなぐリンク(leg_fumer)の定義  -->
  <link name="limb5_link4">
    <inertial>
      <mass value="0.125"/>
      <inertia ixx="0.1" ixy="0.0" ixz="0.0" iyy="0.1" iyz="0.0" izz="0.1"/>
    </inertial>
    <visual>
      <origin rpy="0 3.141592653589793 -1.5707963267948966" xyz="0.05 -0.055 0"/>
      <geometry>
        <mesh filename="package://dual_leg_controller/model/meshes/link2_1.stl" scale="0.001 0.001 0.001"/>
      </geometry>
      <material name="steel_satin"/>
    </visual>
    <collision>
      <origin rpy="0 3.141592653589793 -1.5707963267948966" xyz="0.05 -0.055 0"/>
      <geometry>
        <mesh filename="package://dual_leg_controller/model/meshes/link2_1.stl" scale="0.001 0.001 0.001"/>
      </geometry>
    </collision>
  </link>
  <link name="limb5_link6">
    <inertial>
      <origin rpy="0 0 0" xyz="0 0 0"/>
      <mass value="0.125"/>
      <inertia ixx="0.1" ixy="0.0" ixz="0.0" iyy="0.1" iyz="0.0" izz="0.1"/>
    </inertial>
    <visual>
      <origin rpy="3.141592653589793 0 3.141592653589793" xyz="0.055 0.038 0"/>
      <geometry>
        <mesh filename="package://dual_leg_controller/model/meshes/link3_1.stl" scale="0.001 0.001 0.001"/>
      </geometry>
      <material name="steel_satin"/>
    </visual>
    <collision>
      <origin rpy="3.141592653589793 0 3.141592653589793" xyz="0.055 0.038 0"/>
      <geometry>
        <mesh filename="package://dual_leg_controller/model/meshes/link3_1.stl" scale="0.001 0.001 0.001"/>
      </geometry>
    </collision>
    <!-- 座標系確認用の軸表示を追加 -->
    <visual name="debug_x_axis">
      <origin rpy="0 1.5707963267948966 0" xyz="0.02 0 0"/>
      <geometry>
        <cylinder length="0.04" radius="0.002"/>
      </geometry>
      <material name="debug_red">
        <color rgba="1.0 0.0 0.0 1.0"/>
      </material>
    </visual>
    <visual name="debug_y_axis">
      <origin rpy="1.5707963267948966 0 0" xyz="0 0.02 0"/>
      <geometry>
        <cylinder length="0.04" radius="0.002"/>
      </geometry>
      <material name="debug_green">
        <color rgba="0.0 1.0 0.0 1.0"/>
      </material>
    </visual>
    <visual name="debug_z_axis">
      <origin rpy="0 0 0" xyz="0 0 0.02"/>
      <geometry>
        <cylinder length="0.04" radius="0.002"/>
      </geometry>
      <material name="debug_blue">
        <color rgba="0.0 0.0 1.0 1.0"/>
      </material>
    </visual>
  </link>
  <!-- 脚先（foot_tip）を示す非常に小さなリンク -->
  <link name="limb5_foot_tip">
    <inertial>
      <origin rpy="0 0 0" xyz="0 0 0"/>
      <mass value="0.0001"/>
      <inertia ixx="0.00001" ixy="0.0" ixz="0.0" iyy="0.00001" iyz="0.0" izz="0.00001"/>
    </inertial>
    <!-- X軸（前方向）- 赤色 -->
    <visual name="x_axis">
      <origin rpy="0 1.5707963267948966 0" xyz="0.01 0 0"/>
      <geometry>
        <cylinder length="0.02" radius="0.001"/>
      </geometry>
      <material name="red">
        <color rgba="1.0 0.0 0.0 1.0"/>
      </material>
    </visual>
    <!-- Y軸（右方向）- 緑色 -->
    <visual name="y_axis">
      <origin rpy="1.5707963267948966 0 0" xyz="0 0.01 0"/>
      <geometry>
        <cylinder length="0.02" radius="0.001"/>
      </geometry>
      <material name="green">
        <color rgba="0.0 1.0 0.0 1.0"/>
      </material>
    </visual>
    <!-- Z軸（上方向）- 青色 -->
    <visual name="z_axis">
      <origin rpy="0 0 0" xyz="0 0 0.01"/>
      <geometry>
        <cylinder length="0.02" radius="0.001"/>
      </geometry>
      <material name="blue">
        <color rgba="0.0 0.0 1.0 1.0"/>
      </material>
    </visual>
    <!-- 座標原点 - 白色 -->
    <visual name="origin">
      <origin rpy="0 0 0" xyz="0 0 0"/>
      <geometry>
        <sphere radius="0.003"/>
      </geometry>
      <material name="white">
        <color rgba="1.0 1.0 1.0 1.0"/>
      </material>
    </visual>
  </link>
  <!--joint の定義-->
  <!-- base と motor を固定するジョイント -->
  <joint name="body_motor_fixedjoint_limb5" type="fixed">
    <origin rpy="0 3.141592653589793 9.948376736367678" xyz="0.047500000000000014 -0.08227241335952167 -0.02"/>
    <parent link="body_link"/>
    <child link="motor5"/>
  </joint>
  <!-- motor と leg_coxa　をジョイント-->
  <joint name="limb5_joint1" type="continuous">
    <origin rpy="0 0 3.141592653589793" xyz="0 0 0.05"/>
    <parent link="motor5"/>
    <child link="limb5_link2"/>
    <axis xyz="0.0 0.0 1.0"/>
  </joint>
  <!-- leg_coxa と leg_fumer　をジョイント-->
  <joint name="limb5_joint2" type="continuous">
    <origin rpy="0 1.5707963267948966 0" xyz="0.0 -0.0145 0"/>
    <parent link="limb5_link2"/>
    <child link="limb5_link4"/>
    <axis xyz="0.0 -1.0 0.0"/>
  </joint>
  <!-- leg_fumer と leg_tibia　をジョイント-->
  <joint name="limb5_joint3" type="continuous">
    <origin rpy="0 0 0" xyz="-0.105 0.0 0"/>
    <parent link="limb5_link4"/>
    <child link="limb5_link6"/>
    <axis xyz="0.0 1.0 0.0"/>
  </joint>
  <!-- tibiaリンクと脚先を接続する固定ジョイント -->
  <joint name="limb5_foot_joint" type="fixed">
    <!-- tibiaのSTLモデルの先端までの距離を設定 -->
    <origin rpy="-1.5707963267948966 0 -1.5707963267948966" xyz="-0.103 0.0205 -0.00205"/>
    <parent link="limb5_link6"/>
    <child link="limb5_foot_tip"/>
  </joint>
  <!-- トランスミッション -->
  <transmission name="trans5_1">
    <type>transmission_interface/SimpleTransmission</type>
    <joint name="limb5_joint1">
      <hardwareInterface>hardware_interface/EffortJointInterface</hardwareInterface>
    </joint>
    <actuator name="motor5_1">
      <hardwareInterface>hardware_interface/EffortJointInterface</hardwareInterface>
      <mechanicalReduction>1</mechanicalReduction>
    </actuator>
  </transmission>
  <transmission name="trans5_2">
    <type>transmission_interface/SimpleTransmission</type>
    <joint name="limb5_joint2">
      <hardwareInterface>hardware_interface/EffortJointInterface</hardwareInterface>
    </joint>
    <actuator name="motor5_2">
      <hardwareInterface>hardware_interface/EffortJointInterface</hardwareInterface>
      <mechanicalReduction>1</mechanicalReduction>
    </actuator>
  </transmission>
  <transmission name="trans5_3">
    <type>transmission_interface/SimpleTransmission</type>
    <joint name="limb5_joint3">
      <hardwareInterface>hardware_interface/EffortJointInterface</hardwareInterface>
    </joint>
    <actuator name="motor5_3">
      <hardwareInterface>hardware_interface/EffortJointInterface</hardwareInterface>
      <mechanicalReduction>1</mechanicalReduction>
    </actuator>
  </transmission>
  <gazebo>
    <plugin filename="libgazebo_ros_control.so" name="gazebo_ros_control">
      <robotNamespace>/multileg</robotNamespace>
    </plugin>
  </gazebo>
</robot>

